Workbook

Sheet 1. Inicio
B2: Contabilidad Financiera — Sección 2
B3: Trimestre 3/2026 · ESEN · Profesora Antonia Caballero de Siman
B5: UNIDAD 1 — PASIVO CORRIENTE: PLANILLAS
B7: Nombre del estudiante: | C7: Carlos Alberto Navas Flores
B8: Carnet: | C8: 20255766
B9: Fecha de entrega: | C9: (completar antes de entregar)
B11: 📜 Código de Honor
B12: "Por mi honor y ante mis compañeros, me comprometo a que esta actividad académica refleje mi verdadero nivel de conocimientos, evitando realizar cualquier forma de deshonestidad académica (por ejemplo, copiar o plagiar)."
B17: 🗂️ Guía de las hojas de este archivo
B18: 1. Inicio | C18: Esta hoja: portada, código de honor, guía y leyenda de colores.
B19: 2. Marco Normativo | C19: Tasas ISSS/AFP/INCAF, tablas de retención de ISR y salario mínimo vigentes — fuente: PDF de la clase.
B20: 3. Cálculo Planillas | C20: Ejercicio 1 resuelto: planilla de la empresa ABC (Ana Martínez, Juan López).
B21: 4. Cálculo Práctica | C21: Plantilla en blanco para que agregues tus propios empleados.
B22: 5. Asientos Resueltos | C22: Libro diario del Ejercicio 1, enlazado por fórmula a la Hoja 3.
B23: 6. Asientos Práctica | C23: Plantilla en blanco enlazada a la Hoja 4.
B24: 7. Producto Final | C24: Cédula de prestaciones laborales (vacaciones, aguinaldo, indemnización, renuncia voluntaria) resuelta.
B25: 8. Producto Final Práctica | C25: Plantilla en blanco de la misma cédula.
B27: 🎨 Leyenda de colores
C28: Fila de cuenta de Activo
C29: Fila de cuenta de Pasivo
C30: Fila de cuenta de Patrimonio
C31: Fila de cuenta de Ingreso
C32: Fila de cuenta de Gasto
C33: Celda con fórmula / total calculado
C34: Referencia de marco legal
C35: Celda de práctica por completar (con texto guía en gris)
C36: Nota o instrucción pedagógica
B38: Convención de texto:
B39: Azul | C39: → dato de entrada que puedes cambiar (sueldo, años de servicio, etc.)
B40: Negro | C40: → fórmula o cálculo automático — no lo sobrescribas
B41: Gris | C41: → nota, instrucción o texto explicativo

Sheet 2. Marco Normativo
B2: ⚖️ Marco Normativo — Unidad 1: Pasivo Corriente (Planillas)
B3: Fuente: "Unidad I e Introducción.pdf" (verificado) y tablas de ISR/salario mínimo confirmadas por el estudiante — 2026-08-26. No editar: estas celdas alimentan las fórmulas de las demás hojas.
B5: Tasas de cotización obligatorias
B6: Concepto | C6: Retención Empleado | D6: Aporte Patronal | E6: Base de cálculo
B7: ISSS (Seguro Social) | C7: 0.03 | D7: 0.075 | E7: Tope máximo: base ISSS ($) → | F7: 1000
B8: AFP (Pensiones) | C8: 0.0725 | D8: 0.0875 | E8: Sin límite máximo
B9: INCAF | C9: — | D9: 0.01 | E9: Sobre el total del salario
B10: Tabla de retención de ISR — pagadera MENSUALMENTE
B11: Tramo | C11: Desde | D11: Hasta | E11: % a aplicar | F11: Sobre el exceso de | G11: Más cuota fija de
B12: I | C12: 0.01 | D12: 550 | E12: 0 | F12: 0 | G12: 0
B13: II | C13: 550.01 | D13: 895.24 | E13: 0.1 | F13: 550 | G13: 17.67
B14: III | C14: 895.25 | D14: 2038.1 | E14: 0.2 | F14: 895.24 | G14: 60
B15: IV | C15: 2038.11 | D15: En adelante | E15: 0.3 | F15: 2038.1 | G15: 288.57
B17: Tabla de retención de ISR — pagadera QUINCENALMENTE
B18: Tramo | C18: Desde | D18: Hasta | E18: % a aplicar | F18: Sobre el exceso de | G18: Más cuota fija de
B19: I | C19: 0.01 | D19: 275 | E19: 0 | F19: 0 | G19: 0
B20: II | C20: 275.01 | D20: 447.62 | E20: 0.1 | F20: 275 | G20: 8.83
B21: III | C21: 447.63 | D21: 1019.05 | E21: 0.2 | F21: 447.62 | G21: 30
B22: IV | C22: 1019.06 | D22: En adelante | E22: 0.3 | F22: 1019.05 | G22: 144.28
B24: Tabla de retención de ISR — pagadera SEMANALMENTE
B25: Tramo | C25: Desde | D25: Hasta | E25: % a aplicar | F25: Sobre el exceso de | G25: Más cuota fija de
B26: I | C26: 0.01 | D26: 137.5 | E26: 0 | F26: 0 | G26: 0
B27: II | C27: 137.51 | D27: 223.81 | E27: 0.1 | F27: 137.5 | G27: 4.42
B28: III | C28: 223.82 | D28: 509.52 | E28: 0.2 | F28: 223.81 | G28: 15
B29: IV | C29: 509.53 | D29: En adelante | E29: 0.3 | F29: 509.52 | G29: 72.14
B31: Tabla de recálculo de ISR — JUNIO (1er recálculo, acumulado ene-jun)
B32: Tramo | C32: Desde | D32: Hasta | E32: % a aplicar | F32: Sobre el exceso de | G32: Más cuota fija de
B33: I | C33: 0.01 | D33: 3300 | E33: 0 | F33: 0 | G33: 0
B34: II | C34: 3300.01 | D34: 5371.44 | E34: 0.1 | F34: 3300 | G34: 106.2
B35: III | C35: 5371.45 | D35: 12228.6 | E35: 0.2 | F35: 5371.44 | G35: 360
B36: IV | C36: 12228.61 | D36: En adelante | E36: 0.3 | F36: 12228.6 | G36: 1731.42
B38: Tabla de recálculo de ISR — DICIEMBRE (2do recálculo, acumulado ene-dic)
B39: Tramo | C39: Desde | D39: Hasta | E39: % a aplicar | F39: Sobre el exceso de | G39: Más cuota fija de
B40: I | C40: 0.01 | D40: 6600 | E40: 0 | F40: 0 | G40: 0
B41: II | C41: 6600.01 | D41: 10742.86 | E41: 0.1 | F41: 6600 | G41: 212.12
B42: III | C42: 10742.87 | D42: 24457.14 | E42: 0.2 | F42: 10742.86 | G42: 720
B43: IV | C43: 24457.15 | D43: En adelante | E43: 0.3 | F43: 24457.14 | G43: 3462.86
B45: Salario mínimo vigente (desde 1 de junio de 2025 — Ministerio de Trabajo, verificado 2026-08-26)
B46: Sector económico | C46: Salario mínimo mensual
B47: Industria | C47: 408.8
...

Sheet 3. Cálculo Planillas
B2: 🧮 Cálculo de Planilla — Ejercicio 1 (resuelto)
B3: Empresa ABC, al 31 de mayo. Empleado(s): Ana Martínez (Vendedora) y Juan López (Gerente).
B4: Empleado | C4: Puesto | D4: Sueldo Mensual | E4: Horas Extra ($) | F4: Total Salario | G4: Base ISSS (topada) | H4: ISSS Empleado | I4: AFP Empleado | J4: Remun. Gravada | K4: ISR | L4: Salario Líquido | M4: ISSS Patronal | N4: AFP Patronal | O4: INCAF Patronal | P4: ¿Por qué? (razonamiento)
B5: Ana Martínez | C5: Vendedora | D5: 590 | E5: 10 | F5: =D5+E5 | G5: =MIN(F5,'2. Marco Normativo'!$F$7) | H5: =ROUND(G5*'2. Marco Normativo'!$C$7,2) | I5: =ROUND(F5*'2. Marco Normativo'!$C$8,2) | J5: =F5-H5-I5 | K5: =IF(J5=0,0,ROUND((J5-VLOOKUP(J5,'2. Marco Normativo'!$C$12:$G$15,4,TRUE))*VLOOKUP(J5,'2. Marco Normativo'!$C$12:$G$15,3,TRUE)+VLOOKUP(J5,'2. Marco Normativo'!$C$12:$G$15,5,TRUE),2)) | L5: =F5-H5-I5-K5 | M5: =ROUND(G5*'2. Marco Normativo'!$D$7,2) | N5: =ROUND(F5*'2. Marco Normativo'!$D$8,2) | O5: =ROUND(F5*'2. Marco Normativo'!$D$9,2) | P5: ISSS topado no aplica: el bruto ($600) está por debajo de $1,000.
B6: Juan López | C6: Gerente | D6: 2500 | E6: 0 | F6: =D6+E6 | G6: =MIN(F6,'2. Marco Normativo'!$F$7) | H6: =ROUND(G6*'2. Marco Normativo'!$C$7,2) | I6: =ROUND(F6*'2. Marco Normativo'!$C$8,2) | J6: =F6-H6-I6 | K6: =IF(J6=0,0,ROUND((J6-VLOOKUP(J6,'2. Marco Normativo'!$C$12:$G$15,4,TRUE))*VLOOKUP(J6,'2. Marco Normativo'!$C$12:$G$15,3,TRUE)+VLOOKUP(J6,'2. Marco Normativo'!$C$12:$G$15,5,TRUE),2)) | L6: =F6-H6-I6-K6 | M6: =ROUND(G6*'2. Marco Normativo'!$D$7,2) | N6: =ROUND(F6*'2. Marco Normativo'!$D$8,2) | O6: =ROUND(F6*'2. Marco Normativo'!$D$9,2) | P6: ISSS SÍ se topa a $1,000 porque el bruto ($2,500) supera el tope.
B7: TOTAL | D7: =SUM(D5:D6) | E7: =SUM(E5:E6) | F7: =SUM(F5:F6) | G7: =SUM(G5:G6) | H7: =SUM(H5:H6) | I7: =SUM(I5:I6) | J7: =SUM(J5:J6) | K7: =SUM(K5:K6) | ... O7: =SUM(O5:O6)

Sheet 4. Cálculo Práctica
B2: 🧮 Cálculo de Planilla — Práctica
B3: Completa los datos de un empleado nuevo en las celdas rosadas (columnas B a D). Las demás columnas se calculan solas.
B4: Empleado | C4: Puesto | D4: Sueldo Mensual | E4: Horas Extra ($) | F4: Total Salario | G4: Base ISSS (topada) | H4: ISSS Empleado | I4: AFP Empleado | J4: Remun. Gravada | K4: ISR | L4: Salario Líquido | M4: ISSS Patronal | N4: AFP Patronal | O4: INCAF Patronal | P4: ¿Por qué? (razonamiento)
B5: Nombre | C5: Puesto | D5: 0 | E5: 0 | F5: =D5+E5 | G5: =MIN(F5,'2. Marco Normativo'!$F$7) | H5: =ROUND(G5*'2. Marco Normativo'!$C$7,2) | I5: =ROUND(F5*'2. Marco Normativo'!$C$8,2) | J5: =F5-H5-I5 | K5: =IF(J5=0,0,ROUND((J5-VLOOKUP(J5,'2. Marco Normativo'!$C$12:$G$15,4,TRUE))*VLOOKUP(J5,'2. Marco Normativo'!$C$12:$G$15,3,TRUE)+VLOOKUP(J5,'2. Marco Normativo'!$C$12:$G$15,5,TRUE),2)) | L5: =F5-H5-I5-K5 | M5: =ROUND(G5*'2. Marco Normativo'!$D$7,2) | N5: =ROUND(F5*'2. Marco Normativo'!$D$8,2) | O5: =ROUND(F5*'2. Marco Normativo'!$D$9,2) | P5: Explica aquí por qué el ISSS se topó o no.
B6: Nombre | C6: Puesto | D6: 0 | E6: 0 | F6: =D6+E6 | G6: =MIN(F6,'2. Marco Normativo'!$F$7) | H6: =ROUND(G6*'2. Marco Normativo'!$C$7,2) | I6: =ROUND(F6*'2. Marco Normativo'!$C$8,2) | J6: =F6-H6-I6 | K6: =IF(J6=0,0,ROUND((J6-VLOOKUP(J6,'2. Marco Normativo'!$C$12:$G$15,4,TRUE))*VLOOKUP(J6,'2. Marco Normativo'!$C$12:$G$15,3,TRUE)+VLOOKUP(J6,'2. Marco Normativo'!$C$12:$G$15,5,TRUE),2)) | L6: =F6-H6-I6-K6 | M6: =ROUND(G6*'2. Marco Normativo'!$D$7,2) | N6: =ROUND(F6*'2. Marco Normativo'!$D$8,2) | O6: =ROUND(F6*'2. Marco Normativo'!$D$9,2) | P6: Explica aquí por qué el ISSS se topó o no.
B7: Nombre | C7: Puesto | D7: 0 | E7: 0 | F7: =D7+E7 | G7: =MIN(F7,'2. Marco Normativo'!$F$7) | H7: =ROUND(G7*'2. Marco Normativo'!$C$7,2) | I7: =ROUND(F7*'2. Marco Normativo'!$C$8,2) | J7: =F7-H7-I7 | K7: =IF(J7=0,0,ROUND((J7-VLOOKUP(J7,'2. Marco Normativo'!$C$12:$G$15,4,TRUE))*VLOOKUP(J7,'2. Marco Normativo'!$C$12:$G$15,3,TRUE)+VLOOKUP(J7,'2. Marco Normativo'!$C$12:$G$15,5,TRUE),2)) | L7: =F7-H7-I7-K7 | M7: =ROUND(G7*'2. Marco Normativo'!$D$7,2) | N7: =ROUND(F7*'2. Marco Normativo'!$D$8,2) | O7: =ROUND(F7*'2. Marco Normativo'!$D$9,2) | P7: Explica aquí por qué el ISSS se topó o no.
B8: TOTAL | D8: =SUM(D5:D7) | E8: =SUM(E5:E7) | F8: =SUM(F5:F7) | G8: =SUM(G5:G7) | H8: =SUM(H5:H7) | I8: =SUM(I5:I7) | J8: =SUM(J5:J7) | K8: =SUM(K5:K7) | ... O8: =SUM(O5:O7)

Sheet 5. Asientos Resueltos
B2: 📒 Libro Diario — Pago de Planilla (resuelto)
B3: Enlazado por fórmula a los totales de la hoja "3. Cálculo Planillas" — si cambias un sueldo allá, estos montos se recalculan solos.
B4: Partida | C4: Cuenta | D4: Clasificación | E4: Debe | F4: Haber | G4: ¿Por qué?
B5: P1 | C5: Gasto de Sueldos y Salarios | D5: Gasto | E5: ='3. Cálculo Planillas'!F7 | G5: Se reconoce el gasto por el total del salario devengado en el período.
B6: P1 | C6: ISSS por Pagar (retención) | D6: Pasivo | F6: ='3. Cálculo Planillas'!H7 | G6: Retención hecha al empleado, pendiente de enterar al ISSS.
B7: P1 | C7: AFP por Pagar (retención) | D7: Pasivo | F7: ='3. Cálculo Planillas'!I7 | G7: Retención hecha al empleado, pendiente de enterar a la AFP.
B8: P1 | C8: ISR Retenido por Pagar | D8: Pasivo | F8: ='3. Cálculo Planillas'!K7 | G8: Retención de ISR según la tabla mensual, pendiente de enterar a Hacienda.
B9: P1 | C9: Sueldos y Salarios por Pagar | D9: Pasivo | F9: ='3. Cálculo Planillas'!L7 | G9: Salario neto que aún no se ha pagado en efectivo al empleado.
B10: P2 | C10: Gasto de Aportaciones Patronales | D10: Gasto | E10: ='3. Cálculo Planillas'!M7+'3. Cálculo Planillas'!N7+'3. Cálculo Planillas'!O7 | G10: Costo patronal adicional: ISSS + AFP + INCAF patronal — no se descuenta al empleado.
B11: P2 | C11: ISSS por Pagar (patronal) | D11: Pasivo | F11: ='3. Cálculo Planillas'!M7 | G11: Aporte patronal pendiente de enterar al ISSS.
B12: P2 | C12: AFP por Pagar (patronal) | D12: Pasivo | F12: ='3. Cálculo Planillas'!N7 | G12: Aporte patronal pendiente de enterar a la AFP.
B13: P2 | C13: INCAF por Pagar | D13: Pasivo | F13: ='3. Cálculo Planillas'!O7 | G13: Aporte patronal del 1% pendiente de enterar al INCAF.
B14: P3 | C14: Sueldos y Salarios por Pagar | D14: Pasivo | E14: ='3. Cálculo Planillas'!L7 | G14: Se cancela el pasivo de sueldos por pagar al desembolsar el efectivo.
B15: P3 | C15: Efectivo y Equivalentes | D15: Activo | F15: ='3. Cálculo Planillas'!L7 | G15: Salida de efectivo por el pago del salario neto a los empleados.
B16: TOTALES | E16: =SUM(E5:E15) | F16: =SUM(F5:F15)
B17: Cuadre (Debe = Haber): | E17: =IF(ROUND(E16-F16,2)=0,"✅ Cuadra","⚠️ Revisar")

Sheet 6. Asientos Práctica
B2: 📒 Libro Diario — Práctica
B3: Registra tú las 3 partidas usando los totales de "4. Cálculo Práctica". Elige la Clasificación con la lista desplegable.
B4: Partida | C4: Cuenta | D4: Clasificación | E4: Debe | F4: Haber | G4: ¿Por qué?
B5: P1/P2/P3 | C5: Nombre de la cuenta | G5: Explica el porqué del movimiento
B6: P1/P2/P3 | C6: Nombre de la cuenta | G6: Explica el porqué del movimiento
B7: P1/P2/P3 | C7: Nombre de la cuenta | G7: Explica el porqué del movimiento
B8: P1/P2/P3 | C8: Nombre de la cuenta | G8: Explica el porqué del movimiento
B9: P1/P2/P3 | C9: Nombre de la cuenta | G9: Explica el porqué del movimiento
B10: P1/P2/P3 | C10: Nombre de la cuenta | G10: Explica el porqué del movimiento
B11: P1/P2/P3 | C11: Nombre de la cuenta | G11: Explica el porqué del movimiento
B12: P1/P2/P3 | C12: Nombre de la cuenta | G12: Explica el porqué del movimiento
B13: P1/P2/P3 | C13: Nombre de la cuenta | G13: Explica el porqué del movimiento
B14: P1/P2/P3 | C14: Nombre de la cuenta | G14: Explica el porqué del movimiento
B15: P1/P2/P3 | C15: Nombre de la cuenta | G15: Explica el porqué del movimiento
B16: TOTALES | E16: =SUM(E5:E15) | F16: =SUM(F5:F15)
B17: Cuadre (Debe = Haber): | E17: =IF(ROUND(E16-F16,2)=0,"✅ Cuadra","⚠️ Revisar")

Sheet 7. Producto Final
B2: 📊 Cédula de Prestaciones Laborales (resuelto)
B3: Ejemplo ilustrativo: los AÑOS DE SERVICIO de Ana y Juan son un supuesto pedagógico del vault (no vienen del enunciado del Ejercicio 1, que no da antigüedad) — solo para mostrar el cálculo completo de la cédula. El sueldo mensual y las tasas sí vienen del ejercicio verificado y de la Hoja 2.
B4: Empleado | C4: Sueldo Mensual | D4: Años de Servicio | E4: Salario Diario | F4: Vacaciones (15d+30%) | G4: Días Aguinaldo | H4: Aguinaldo | I4: Exento (2 SM) | J4: Exceso Gravado | K4: ISR s/ exceso | L4: Indemnización (30d × año) | M4: Renuncia Voluntaria | N4: ¿Por qué?
B5: ='3. Cálculo Planillas'!B5 | C5: ='3. Cálculo Planillas'!D5 | D5: 4 | E5: =ROUND(C5/30,2) | F5: =ROUND(E5*15*1.3,2) | G5: =IF(D5="",0,VLOOKUP(D5,'2. Marco Normativo'!$B$57:$D$59,3,TRUE)) | H5: =ROUND(E5*G5,2) | I5: ='2. Marco Normativo'!$C$48*2 | J5: =MAX(0,H5-I5) | K5: =IF(J5=0,0,ROUND((J5-VLOOKUP(J5,'2. Marco Normativo'!$C$12:$G$15,4,TRUE))*VLOOKUP(J5,'2. Marco Normativo'!$C$12:$G$15,3,TRUE)+VLOOKUP(J5,'2. Marco Normativo'!$C$12:$G$15,5,TRUE),2)) | L5: =ROUND(MIN(E5,ROUND(('2. Marco Normativo'!$C$48*4)/30,2))*30*D5,2) | M5: =ROUND(MIN(E5,ROUND(('2. Marco Normativo'!$C$48*2)/30,2))*15*D5,2) | N5: 4 años de antigüedad → tabla de aguinaldo: 3-10 años = 19 días. Aguinaldo bajo el tope exento (2 SM), no paga ISR. Indemnización con salario diario topado a 4 salarios mínimos diarios (Art. 58, Código de Trabajo).
B6: ='3. Cálculo Planillas'!B6 | C6: ='3. Cálculo Planillas'!D6 | D6: 12 | E6: =ROUND(C6/30,2) | F6: =ROUND(E6*15*1.3,2) | G6: =IF(D6="",0,VLOOKUP(D6,'2. Marco Normativo'!$B$57:$D$59,3,TRUE)) | H6: =ROUND(E6*G6,2) | I6: ='2. Marco Normativo'!$C$48*2 | J6: =MAX(0,H6-I6) | K6: =IF(J6=0,0,ROUND((J6-VLOOKUP(J6,'2. Marco Normativo'!$C$12:$G$15,4,TRUE))*VLOOKUP(J6,'2. Marco Normativo'!$C$12:$G$15,3,TRUE)+VLOOKUP(J6,'2. Marco Normativo'!$C$12:$G$15,5,TRUE),2)) | L6: =ROUND(MIN(E6,ROUND(('2. Marco Normativo'!$C$48*4)/30,2))*30*D6,2) | M6: =ROUND(MIN(E6,ROUND(('2. Marco Normativo'!$C$48*2)/30,2))*15*D6,2) | N6: 12 años de antigüedad → 10+ años = 21 días. Aguinaldo supera el tope exento; el exceso paga ISR. Su salario diario ($83.33) supera el tope de 4 salarios mínimos diarios ($54.51), así que la indemnización se calcula con el tope, no con su salario real — y la renuncia voluntaria se topa a 2 salarios mínimos diarios.

Sheet 8. Producto Final Práct.
B2: 📊 Cédula de Prestaciones Laborales — Práctica
B3: Completa el sueldo y los años de servicio (celdas rosadas). El resto se calcula con las mismas fórmulas de la hoja resuelta.
B4: Empleado | C4: Sueldo Mensual | D4: Años de Servicio | E4: Salario Diario | F4: Vacaciones (15d+30%) | G4: Días Aguinaldo | H4: Aguinaldo | I4: Exento (2 SM) | J4: Exceso Gravado | K4: ISR s/ exceso | L4: Indemnización (30d × año) | M4: Renuncia Voluntaria | N4: ¿Por qué?
B5: ='4. Cálculo Práctica'!B5 | C5: ='4. Cálculo Práctica'!D5 | E5: =ROUND(C5/30,2) | F5: =ROUND(E5*15*1.3,2) | G5: =IF(D5="",0,VLOOKUP(D5,'2. Marco Normativo'!$B$57:$D$59,3,TRUE)) | H5: =ROUND(E5*G5,2) | I5: ='2. Marco Normativo'!$C$48*2 | J5: =MAX(0,H5-I5) | K5: =IF(J5=0,0,ROUND((J5-VLOOKUP(J5,'2. Marco Normativo'!$C$12:$G$15,4,TRUE))*VLOOKUP(J5,'2. Marco Normativo'!$C$12:$G$15,3,TRUE)+VLOOKUP(J5,'2. Marco Normativo'!$C$12:$G$15,5,TRUE),2)) | L5: =ROUND(MIN(E5,ROUND(('2. Marco Normativo'!$C$48*4)/30,2))*30*D5,2) | M5: =ROUND(MIN(E5,ROUND(('2. Marco Normativo'!$C$48*2)/30,2))*15*D5,2) | N5: Explica el resultado de tu ejemplo.
B6: ='4. Cálculo Práctica'!B6 | C6: ='4. Cálculo Práctica'!D6 | E6: =ROUND(C6/30,2) | F6: =ROUND(E6*15*1.3,2) | G6: =IF(D6="",0,VLOOKUP(D6,'2. Marco Normativo'!$B$57:$D$59,3,TRUE)) | H6: =ROUND(E6*G6,2) | I6: ='2. Marco Normativo'!$C$48*2 | J6: =MAX(0,H6-I6) | K6: =IF(J6=0,0,ROUND((J6-VLOOKUP(J6,'2. Marco Normativo'!$C$12:$G$15,4,TRUE))*VLOOKUP(J6,'2. Marco Normativo'!$C$12:$G$15,3,TRUE)+VLOOKUP(J6,'2. Marco Normativo'!$C$12:$G$15,5,TRUE),2)) | L6: =ROUND(MIN(E6,ROUND(('2. Marco Normativo'!$C$48*4)/30,2))*30*D6,2) | M6: =ROUND(MIN(E6,ROUND(('2. Marco Normativo'!$C$48*2)/30,2))*15*D6,2) | N6: Explica el resultado de tu ejemplo.
B7: ='4. Cálculo Práctica'!B7 | C7: ='4. Cálculo Práctica'!D7 | E7: =ROUND(C7/30,2) | F7: =ROUND(E7*15*1.3,2) | G7: =IF(D7="",0,VLOOKUP(D7,'2. Marco Normativo'!$B$57:$D$59,3,TRUE)) | H7: =ROUND(E7*G7,2) | I7: ='2. Marco Normativo'!$C$48*2 | J7: =MAX(0,H7-I7) | K7: =IF(J7=0,0,ROUND((J7-VLOOKUP(J7,'2. Marco Normativo'!$C$12:$G$15,4,TRUE))*VLOOKUP(J7,'2. Marco Normativo'!$C$12:$G$15,3,TRUE)+VLOOKUP(J7,'2. Marco Normativo'!$C$12:$G$15,5,TRUE),2)) | L7: =ROUND(MIN(E7,ROUND(('2. Marco Normativo'!$C$48*4)/30,2))*30*D7,2) | M7: =ROUND(MIN(E7,ROUND(('2. Marco Normativo'!$C$48*2)/30,2))*15*D7,2) | N7: Explica el resultado de tu ejemplo.
